2022-02-27 18:48:59 WARNING: <module 'time' (built-in)> Lies Kryos#1734 947566000801468517 728444080908140575 caused the error "password authentication failed for user "LyesKryos"" using the command recruit
2022-02-28 15:00:15 WARNING: <module 'time' (built-in)> Lies Kryos#1734 947870823719534622 728444080908140575 caused the error "password authentication failed for user "postgres"" using the command recruit
2022-02-28 15:02:15 WARNING: <module 'time' (built-in)> Lies Kryos#1734 947871330173333564 728444080908140575 caused the error "relation "recruitment" does not exist" using the command recruit
2022-02-28 15:25:28 WARNING: <module 'time' (built-in)> Obv_Atlas#6021 947877170179633152 caused the error "Command "template" is not found" using the command template
2022-02-28 15:25:28 WARNING: <module 'time' (built-in)> Obv_Atlas#6021 947877170179633152 674259612580446230 caused the error "Command "template" is not found" using the command template
2022-02-28 15:27:37 WARNING: <module 'time' (built-in)> Obv_Atlas#6021 947877711244836874 caused the error "Command "register_template" is not found" using the command register_template
2022-02-28 15:27:37 WARNING: <module 'time' (built-in)> Obv_Atlas#6021 947877711244836874 674259612580446230 caused the error "Command "register_template" is not found" using the command register_template
2022-02-28 15:47:48 WARNING: <module 'time' (built-in)> Lies Kryos#1734 947882790198861907 728444080908140575 caused the error "Extension 'cogs.recruitment' raised an error: RuntimeError: asyncio.run() cannot be called from a running event loop" using the command reload
2022-02-28 15:52:39 WARNING: <module 'time' (built-in)> Lies Kryos#1734 947884012473577482 728444080908140575 caused the error "Extension 'cogs.recruitment' raised an error: RuntimeError: This event loop is already running" using the command load
2022-02-28 15:58:36 WARNING: <module 'time' (built-in)> Lies Kryos#1734 947885510616051743 728444080908140575 caused the error "Extension 'cogs.recruitment' raised an error: AttributeError: '_UnixSelectorEventLoop' object has no attribute 'run'" using the command load
2022-02-28 16:03:56 WARNING: <module 'time' (built-in)> Lies Kryos#1734 947886852185145365 728444080908140575 caused the error "Extension 'cogs.recruitment' is already loaded." using the command load
2022-02-28 19:02:43 ERROR: _GatheringFuture exception was never retrieved
future: <_GatheringFuture finished exception=OSError(5, 'Input/output error')>
Traceback (most recent call last):
  File "/root/Documents/Shard/cogs/recruitment.py", line 82, in recruitment
    nnsoup = BeautifulSoup(newnationsraw, "lxml")
  File "/usr/local/lib/python3.8/dist-packages/bs4/__init__.py", line 245, in __init__
    raise FeatureNotFound(
bs4.FeatureNotFound: Couldn't find a tree builder with the features you requested: lxml. Do you need to install a parser library?

During handling of the above exception, another exception occurred:

Traceback (most recent call last):
  File "/root/Documents/Shard/cogs/recruitment.py", line 126, in recruitment
    await ctx.send(error)
OSError: [Errno 5] Input/output error
2022-02-28 19:04:00 ERROR: _GatheringFuture exception was never retrieved
future: <_GatheringFuture finished exception=OSError(5, 'Input/output error')>
Traceback (most recent call last):
  File "/root/Documents/Shard/cogs/recruitment.py", line 82, in recruitment
    nnsoup = BeautifulSoup(newnationsraw, "lxml")
  File "/usr/local/lib/python3.8/dist-packages/bs4/__init__.py", line 245, in __init__
    raise FeatureNotFound(
bs4.FeatureNotFound: Couldn't find a tree builder with the features you requested: lxml. Do you need to install a parser library?

During handling of the above exception, another exception occurred:

Traceback (most recent call last):
  File "/root/Documents/Shard/cogs/recruitment.py", line 126, in recruitment
    await ctx.send(error)
OSError: [Errno 5] Input/output error
2022-02-28 19:05:11 ERROR: _GatheringFuture exception was never retrieved
future: <_GatheringFuture finished exception=NameError("name 'logging' is not defined")>
Traceback (most recent call last):
  File "/root/Documents/Shard/cogs/recruitment.py", line 82, in recruitment
    nnsoup = BeautifulSoup(newnationsraw, "lxml")
  File "/usr/local/lib/python3.8/dist-packages/bs4/__init__.py", line 245, in __init__
    raise FeatureNotFound(
bs4.FeatureNotFound: Couldn't find a tree builder with the features you requested: lxml. Do you need to install a parser library?

During handling of the above exception, another exception occurred:

Traceback (most recent call last):
  File "/root/Documents/Shard/cogs/recruitment.py", line 126, in recruitment
    await ctx.send(error)
NameError: name 'logging' is not defined
2022-02-28 19:05:11 ERROR: _GatheringFuture exception was never retrieved
future: <_GatheringFuture finished exception=CancelledError()>
asyncio.exceptions.CancelledError
2022-02-28 19:05:11 ERROR: _GatheringFuture exception was never retrieved
future: <_GatheringFuture finished exception=CancelledError()>
asyncio.exceptions.CancelledError
2022-02-28 19:05:11 ERROR: _GatheringFuture exception was never retrieved
future: <_GatheringFuture finished exception=OSError(5, 'Input/output error')>
Traceback (most recent call last):
  File "/root/Documents/Shard/cogs/recruitment.py", line 82, in recruitment
    nnsoup = BeautifulSoup(newnationsraw, "lxml")
  File "/usr/local/lib/python3.8/dist-packages/bs4/__init__.py", line 245, in __init__
    raise FeatureNotFound(
bs4.FeatureNotFound: Couldn't find a tree builder with the features you requested: lxml. Do you need to install a parser library?

During handling of the above exception, another exception occurred:

Traceback (most recent call last):
  File "/root/Documents/Shard/cogs/recruitment.py", line 126, in recruitment
    await ctx.send(error)
OSError: [Errno 5] Input/output error
2022-02-28 19:07:34 ERROR: Task exception was never retrieved
future: <Task finished name='Task-1' coro=<setup.<locals>.monthly_recruiter_scheduler() done, defined at /root/Documents/Shard/cogs/recruitment.py:520> exception=AttributeError("'NoneType' object has no attribute 'send'")>
Traceback (most recent call last):
  File "/root/Documents/Shard/cogs/recruitment.py", line 532, in monthly_recruiter_scheduler
    await crashchannel.send(f"Monthly recruiter next run: {monthlyjob.next_run_time}")
AttributeError: 'NoneType' object has no attribute 'send'

During handling of the above exception, another exception occurred:

Traceback (most recent call last):
  File "/root/Documents/Shard/cogs/recruitment.py", line 534, in monthly_recruiter_scheduler
    await crashchannel.send(error)
AttributeError: 'NoneType' object has no attribute 'send'
2022-02-28 19:08:21 ERROR: _GatheringFuture exception was never retrieved
future: <_GatheringFuture finished exception=CancelledError()>
asyncio.exceptions.CancelledError
2022-02-28 19:10:23 ERROR: _GatheringFuture exception was never retrieved
future: <_GatheringFuture finished exception=CancelledError()>
asyncio.exceptions.CancelledError
2022-02-28 19:21:54 ERROR: Task exception was never retrieved
future: <Task finished name='Task-1' coro=<setup.<locals>.monthly_recruiter_scheduler() done, defined at /root/Documents/Shard/cogs/recruitment.py:520> exception=AttributeError("'NoneType' object has no attribute 'send'")>
Traceback (most recent call last):
  File "/root/Documents/Shard/cogs/recruitment.py", line 532, in monthly_recruiter_scheduler
    await crashchannel.send(f"Monthly recruiter next run: {monthlyjob.next_run_time}")
AttributeError: 'NoneType' object has no attribute 'send'

During handling of the above exception, another exception occurred:

Traceback (most recent call last):
  File "/root/Documents/Shard/cogs/recruitment.py", line 534, in monthly_recruiter_scheduler
    await crashchannel.send(error)
AttributeError: 'NoneType' object has no attribute 'send'
2022-02-28 22:47:49 ERROR: Task exception was never retrieved
future: <Task finished name='Task-1' coro=<setup.<locals>.monthly_recruiter_scheduler() done, defined at /root/Documents/Shard/cogs/recruitment.py:520> exception=AttributeError("'NoneType' object has no attribute 'send'")>
Traceback (most recent call last):
  File "/root/Documents/Shard/cogs/recruitment.py", line 532, in monthly_recruiter_scheduler
    await crashchannel.send(f"Monthly recruiter next run: {monthlyjob.next_run_time}")
AttributeError: 'NoneType' object has no attribute 'send'

During handling of the above exception, another exception occurred:

Traceback (most recent call last):
  File "/root/Documents/Shard/cogs/recruitment.py", line 534, in monthly_recruiter_scheduler
    await crashchannel.send(error)
AttributeError: 'NoneType' object has no attribute 'send'
2022-03-01 03:24:51 ERROR: _GatheringFuture exception was never retrieved
future: <_GatheringFuture finished exception=CancelledError()>
asyncio.exceptions.CancelledError
2022-03-01 13:29:19 WARNING: <module 'time' (built-in)> Dr_Halred_Van_Richards#6410 948210329467367456 caused the error "Command "recuit" is not found" using the command recuit
2022-03-01 13:29:19 WARNING: <module 'time' (built-in)> Dr_Halred_Van_Richards#6410 948210329467367456 674259612580446230 caused the error "Command "recuit" is not found" using the command recuit
2022-03-01 13:29:41 ERROR: _GatheringFuture exception was never retrieved
future: <_GatheringFuture finished exception=CancelledError()>
asyncio.exceptions.CancelledError
2022-03-01 16:37:33 ERROR: _GatheringFuture exception was never retrieved
future: <_GatheringFuture finished exception=CancelledError()>
asyncio.exceptions.CancelledError
2022-03-01 16:41:35 ERROR: _GatheringFuture exception was never retrieved
future: <_GatheringFuture finished exception=CancelledError()>
asyncio.exceptions.CancelledError
2022-03-01 16:45:51 WARNING: <module 'time' (built-in)> DolphinDiverBCT#7954 948259789111169044 674259612580446230 caused the error "'NoneType' object has no attribute 'id'" using the command recruiter
2022-03-01 16:47:15 WARNING: <module 'time' (built-in)> Lies Kryos#1734 948260136533786704 caused the error "Command "instructions" is not found" using the command instructions
2022-03-01 16:47:15 WARNING: <module 'time' (built-in)> Lies Kryos#1734 948260136533786704 674259612580446230 caused the error "Command "instructions" is not found" using the command instructions
2022-03-01 16:49:14 ERROR: _GatheringFuture exception was never retrieved
future: <_GatheringFuture finished exception=CancelledError()>
asyncio.exceptions.CancelledError
2022-03-01 17:55:09 ERROR: _GatheringFuture exception was never retrieved
future: <_GatheringFuture finished exception=CancelledError()>
asyncio.exceptions.CancelledError
2022-03-01 18:33:24 ERROR: _GatheringFuture exception was never retrieved
future: <_GatheringFuture finished exception=CancelledError()>
asyncio.exceptions.CancelledError
2022-03-01 19:25:05 WARNING: <module 'time' (built-in)> Lies Kryos#1734 948299858928885781 674259612580446230 caused the error "'NoneType' object has no attribute 'id'" using the command recruiter
2022-03-01 19:27:49 WARNING: <module 'time' (built-in)> Lies Kryos#1734 948300549051265036 728444080908140575 caused the error "Extension 'cogs.recruiter' has not been loaded." using the command reload
2022-03-01 21:06:38 ERROR: _GatheringFuture exception was never retrieved
future: <_GatheringFuture finished exception=CancelledError()>
asyncio.exceptions.CancelledError
2022-03-01 21:10:58 WARNING: <module 'time' (built-in)> Obv_Atlas#6021 948326507531608114 caused the error "Command "STOP" is not found" using the command STOP
2022-03-01 21:10:58 WARNING: <module 'time' (built-in)> Obv_Atlas#6021 948326507531608114 674259612580446230 caused the error "Command "STOP" is not found" using the command STOP
2022-03-01 23:39:05 ERROR: _GatheringFuture exception was never retrieved
future: <_GatheringFuture finished exception=CancelledError()>
asyncio.exceptions.CancelledError
2022-03-01 23:54:37 ERROR: _GatheringFuture exception was never retrieved
future: <_GatheringFuture finished exception=CancelledError()>
asyncio.exceptions.CancelledError
2022-03-02 08:27:30 ERROR: _GatheringFuture exception was never retrieved
future: <_GatheringFuture finished exception=CancelledError()>
asyncio.exceptions.CancelledError
2022-03-02 16:31:06 ERROR: _GatheringFuture exception was never retrieved
future: <_GatheringFuture finished exception=CancelledError()>
asyncio.exceptions.CancelledError
2022-03-02 17:25:36 ERROR: _GatheringFuture exception was never retrieved
future: <_GatheringFuture finished exception=CancelledError()>
asyncio.exceptions.CancelledError
2022-03-02 17:50:44 ERROR: _GatheringFuture exception was never retrieved
future: <_GatheringFuture finished exception=CancelledError()>
asyncio.exceptions.CancelledError
2022-03-02 18:45:53 ERROR: _GatheringFuture exception was never retrieved
future: <_GatheringFuture finished exception=CancelledError()>
asyncio.exceptions.CancelledError
2022-03-02 20:14:46 ERROR: _GatheringFuture exception was never retrieved
future: <_GatheringFuture finished exception=CancelledError()>
asyncio.exceptions.CancelledError
2022-03-02 20:53:08 ERROR: _GatheringFuture exception was never retrieved
future: <_GatheringFuture finished exception=CancelledError()>
asyncio.exceptions.CancelledError
2022-03-02 21:35:59 ERROR: _GatheringFuture exception was never retrieved
future: <_GatheringFuture finished exception=CancelledError()>
asyncio.exceptions.CancelledError
2022-03-02 23:27:55 ERROR: _GatheringFuture exception was never retrieved
future: <_GatheringFuture finished exception=CancelledError()>
asyncio.exceptions.CancelledError
2022-03-02 23:27:55 ERROR: _GatheringFuture exception was never retrieved
future: <_GatheringFuture finished exception=CancelledError()>
asyncio.exceptions.CancelledError
2022-03-02 23:27:55 ERROR: _GatheringFuture exception was never retrieved
future: <_GatheringFuture finished exception=CancelledError()>
asyncio.exceptions.CancelledError
2022-03-02 23:27:55 ERROR: _GatheringFuture exception was never retrieved
future: <_GatheringFuture finished exception=CancelledError()>
asyncio.exceptions.CancelledError
2022-03-03 00:16:18 WARNING: <module 'time' (built-in)> Lies Kryos#1734 948735537089511444 caused the error "Command "customize_recruiter_role" is not found" using the command customize_recruiter_role
2022-03-03 00:16:18 WARNING: <module 'time' (built-in)> Lies Kryos#1734 948735537089511444 674259612580446230 caused the error "Command "customize_recruiter_role" is not found" using the command customize_recruiter_role
2022-03-03 01:38:28 WARNING: <module 'time' (built-in)> Dr_Halred_Van_Richards#6410 948756214609743952 caused the error "Command "recriut" is not found" using the command recriut
2022-03-03 01:38:28 WARNING: <module 'time' (built-in)> Dr_Halred_Van_Richards#6410 948756214609743952 674259612580446230 caused the error "Command "recriut" is not found" using the command recriut
2022-03-03 01:38:53 ERROR: _GatheringFuture exception was never retrieved
future: <_GatheringFuture finished exception=CancelledError()>
asyncio.exceptions.CancelledError
2022-03-03 06:43:41 ERROR: _GatheringFuture exception was never retrieved
future: <_GatheringFuture finished exception=CancelledError()>
asyncio.exceptions.CancelledError
2022-03-03 07:18:44 ERROR: _GatheringFuture exception was never retrieved
future: <_GatheringFuture finished exception=CancelledError()>
asyncio.exceptions.CancelledError
2022-03-03 07:22:40 ERROR: _GatheringFuture exception was never retrieved
future: <_GatheringFuture finished exception=CancelledError()>
asyncio.exceptions.CancelledError
2022-03-03 08:00:33 ERROR: _GatheringFuture exception was never retrieved
future: <_GatheringFuture finished exception=CancelledError()>
asyncio.exceptions.CancelledError
2022-03-03 08:19:55 WARNING: <module 'time' (built-in)> Secret#1982 948857243217051658 caused the error "Command "customize_recruiter_role[380474]" is not found" using the command customize_recruiter_role[380474]
2022-03-03 08:19:55 WARNING: <module 'time' (built-in)> Secret#1982 948857243217051658 674259612580446230 caused the error "Command "customize_recruiter_role[380474]" is not found" using the command customize_recruiter_role[380474]
2022-03-03 08:27:03 ERROR: _GatheringFuture exception was never retrieved
future: <_GatheringFuture finished exception=CancelledError()>
asyncio.exceptions.CancelledError
2022-03-03 15:11:01 WARNING: <module 'time' (built-in)> Kosciuszko#1945 948960699663667220 caused the error "Command "template" is not found" using the command template
2022-03-03 15:11:01 WARNING: <module 'time' (built-in)> Kosciuszko#1945 948960699663667220 674259612580446230 caused the error "Command "template" is not found" using the command template
2022-03-03 15:12:11 ERROR: _GatheringFuture exception was never retrieved
future: <_GatheringFuture finished exception=CancelledError()>
asyncio.exceptions.CancelledError
2022-03-03 16:34:12 ERROR: _GatheringFuture exception was never retrieved
future: <_GatheringFuture finished exception=CancelledError()>
asyncio.exceptions.CancelledError
2022-03-03 18:05:26 ERROR: _GatheringFuture exception was never retrieved
future: <_GatheringFuture finished exception=CancelledError()>
asyncio.exceptions.CancelledError
2022-03-03 18:05:43 WARNING: <module 'time' (built-in)> DolphinDiverBCT#7954 949004661766119494 caused the error "Command "sto" is not found" using the command sto
2022-03-03 18:05:43 WARNING: <module 'time' (built-in)> DolphinDiverBCT#7954 949004661766119494 674259612580446230 caused the error "Command "sto" is not found" using the command sto
2022-03-03 18:57:32 ERROR: _GatheringFuture exception was never retrieved
future: <_GatheringFuture finished exception=CancelledError()>
asyncio.exceptions.CancelledError
2022-03-04 02:19:46 WARNING: <module 'time' (built-in)> EinZwei#6969 949128995864199199 caused the error "Command "recuiter" is not found" using the command recuiter
2022-03-04 02:19:46 WARNING: <module 'time' (built-in)> EinZwei#6969 949128995864199199 674259612580446230 caused the error "Command "recuiter" is not found" using the command recuiter
2022-03-04 03:47:49 ERROR: _GatheringFuture exception was never retrieved
future: <_GatheringFuture finished exception=CancelledError()>
asyncio.exceptions.CancelledError
2022-03-04 04:15:22 ERROR: _GatheringFuture exception was never retrieved
future: <_GatheringFuture finished exception=CancelledError()>
asyncio.exceptions.CancelledError
2022-03-04 06:28:03 ERROR: _GatheringFuture exception was never retrieved
future: <_GatheringFuture finished exception=CancelledError()>
asyncio.exceptions.CancelledError
2022-03-04 07:52:34 ERROR: _GatheringFuture exception was never retrieved
future: <_GatheringFuture finished exception=CancelledError()>
asyncio.exceptions.CancelledError
2022-03-04 08:25:56 ERROR: _GatheringFuture exception was never retrieved
future: <_GatheringFuture finished exception=CancelledError()>
asyncio.exceptions.CancelledError
2022-03-04 13:16:01 ERROR: _GatheringFuture exception was never retrieved
future: <_GatheringFuture finished exception=CancelledError()>
asyncio.exceptions.CancelledError
2022-03-04 14:40:36 ERROR: _GatheringFuture exception was never retrieved
future: <_GatheringFuture finished exception=CancelledError()>
asyncio.exceptions.CancelledError
2022-03-04 14:40:36 ERROR: _GatheringFuture exception was never retrieved
future: <_GatheringFuture finished exception=CancelledError()>
asyncio.exceptions.CancelledError
2022-03-04 14:58:44 ERROR: _GatheringFuture exception was never retrieved
future: <_GatheringFuture finished exception=CancelledError()>
asyncio.exceptions.CancelledError
2022-03-04 16:27:43 WARNING: <module 'time' (built-in)> Kosciuszko#1945 949342386989985862 674259612580446230 caused the error "400 Bad Request (error code: 50006): Cannot send an empty message" using the command rank
2022-03-04 16:29:17 WARNING: <module 'time' (built-in)> Lies Kryos#1734 949342781690761357 674259612580446230 caused the error "400 Bad Request (error code: 50006): Cannot send an empty message" using the command rank
2022-03-04 16:29:37 ERROR: _GatheringFuture exception was never retrieved
future: <_GatheringFuture finished exception=CancelledError()>
asyncio.exceptions.CancelledError
2022-03-04 18:31:57 ERROR: _GatheringFuture exception was never retrieved
future: <_GatheringFuture finished exception=CancelledError()>
asyncio.exceptions.CancelledError
2022-03-04 19:56:35 WARNING: <module 'time' (built-in)> Secret#1982 949394952893394954 674259612580446230 caused the error "400 Bad Request (error code: 50006): Cannot send an empty message" using the command rank
2022-03-04 19:59:23 ERROR: _GatheringFuture exception was never retrieved
future: <_GatheringFuture finished exception=CancelledError()>
asyncio.exceptions.CancelledError
2022-03-04 21:21:39 ERROR: _GatheringFuture exception was never retrieved
future: <_GatheringFuture finished exception=CancelledError()>
asyncio.exceptions.CancelledError
2022-03-04 21:23:11 ERROR: _GatheringFuture exception was never retrieved
future: <_GatheringFuture finished exception=CancelledError()>
asyncio.exceptions.CancelledError
2022-03-04 21:40:44 ERROR: _GatheringFuture exception was never retrieved
future: <_GatheringFuture finished exception=CancelledError()>
asyncio.exceptions.CancelledError
2022-03-04 22:09:27 WARNING: <module 'time' (built-in)> DolphinDiverBCT#7954 949428387418607657 caused the error "Command "reccruit" is not found" using the command reccruit
2022-03-04 22:09:27 WARNING: <module 'time' (built-in)> DolphinDiverBCT#7954 949428387418607657 674259612580446230 caused the error "Command "reccruit" is not found" using the command reccruit
2022-03-04 22:09:30 ERROR: _GatheringFuture exception was never retrieved
future: <_GatheringFuture finished exception=CancelledError()>
asyncio.exceptions.CancelledError
2022-03-04 22:09:55 WARNING: <module 'time' (built-in)> DolphinDiverBCT#7954 949428506956271657 caused the error "Command "stopo" is not found" using the command stopo
2022-03-04 22:09:55 WARNING: <module 'time' (built-in)> DolphinDiverBCT#7954 949428506956271657 674259612580446230 caused the error "Command "stopo" is not found" using the command stopo
2022-03-05 03:05:54 ERROR: _GatheringFuture exception was never retrieved
future: <_GatheringFuture finished exception=CancelledError()>
asyncio.exceptions.CancelledError
2022-03-05 03:55:14 ERROR: _GatheringFuture exception was never retrieved
future: <_GatheringFuture finished exception=CancelledError()>
asyncio.exceptions.CancelledError
2022-03-05 04:35:45 ERROR: _GatheringFuture exception was never retrieved
future: <_GatheringFuture finished exception=CancelledError()>
asyncio.exceptions.CancelledError
2022-03-05 06:45:27 ERROR: _GatheringFuture exception was never retrieved
future: <_GatheringFuture finished exception=CancelledError()>
asyncio.exceptions.CancelledError
2022-03-05 08:30:11 ERROR: _GatheringFuture exception was never retrieved
future: <_GatheringFuture finished exception=CancelledError()>
asyncio.exceptions.CancelledError
2022-03-05 09:00:52 WARNING: <module 'time' (built-in)> DolphinDiverBCT#7954 949592322826444820 caused the error "Command "ank" is not found" using the command ank
2022-03-05 09:00:52 WARNING: <module 'time' (built-in)> DolphinDiverBCT#7954 949592322826444820 674259612580446230 caused the error "Command "ank" is not found" using the command ank
2022-03-05 14:12:14 ERROR: _GatheringFuture exception was never retrieved
future: <_GatheringFuture finished exception=CancelledError()>
asyncio.exceptions.CancelledError
2022-03-05 14:36:19 ERROR: _GatheringFuture exception was never retrieved
future: <_GatheringFuture finished exception=CancelledError()>
asyncio.exceptions.CancelledError
2022-03-05 15:20:18 ERROR: _GatheringFuture exception was never retrieved
future: <_GatheringFuture finished exception=CancelledError()>
asyncio.exceptions.CancelledError
2022-03-05 17:23:43 ERROR: _GatheringFuture exception was never retrieved
future: <_GatheringFuture finished exception=CancelledError()>
asyncio.exceptions.CancelledError
2022-03-05 18:02:21 ERROR: _GatheringFuture exception was never retrieved
future: <_GatheringFuture finished exception=CancelledError()>
asyncio.exceptions.CancelledError
2022-03-05 18:21:06 ERROR: _GatheringFuture exception was never retrieved
future: <_GatheringFuture finished exception=CancelledError()>
asyncio.exceptions.CancelledError
2022-03-05 18:24:07 WARNING: <module 'time' (built-in)> Lies Kryos#1734 949734067644010526 674259612580446230 caused the error "400 Bad Request (error code: 50006): Cannot send an empty message" using the command rank
2022-03-05 18:24:36 WARNING: <module 'time' (built-in)> Lies Kryos#1734 949734192512638976 674259612580446230 caused the error "400 Bad Request (error code: 50006): Cannot send an empty message" using the command rank
2022-03-05 18:45:46 ERROR: _GatheringFuture exception was never retrieved
future: <_GatheringFuture finished exception=CancelledError()>
asyncio.exceptions.CancelledError
2022-03-05 20:29:15 ERROR: _GatheringFuture exception was never retrieved
future: <_GatheringFuture finished exception=CancelledError()>
asyncio.exceptions.CancelledError
2022-03-05 20:32:11 ERROR: _GatheringFuture exception was never retrieved
future: <_GatheringFuture finished exception=CancelledError()>
asyncio.exceptions.CancelledError
2022-03-05 22:13:52 ERROR: _GatheringFuture exception was never retrieved
future: <_GatheringFuture finished exception=CancelledError()>
asyncio.exceptions.CancelledError
2022-03-05 22:37:48 ERROR: _GatheringFuture exception was never retrieved
future: <_GatheringFuture finished exception=CancelledError()>
asyncio.exceptions.CancelledError
2022-03-06 01:25:22 ERROR: _GatheringFuture exception was never retrieved
future: <_GatheringFuture finished exception=CancelledError()>
asyncio.exceptions.CancelledError
2022-03-06 06:30:55 ERROR: _GatheringFuture exception was never retrieved
future: <_GatheringFuture finished exception=CancelledError()>
asyncio.exceptions.CancelledError
2022-03-06 06:50:35 ERROR: _GatheringFuture exception was never retrieved
future: <_GatheringFuture finished exception=CancelledError()>
asyncio.exceptions.CancelledError
2022-03-06 07:15:47 ERROR: _GatheringFuture exception was never retrieved
future: <_GatheringFuture finished exception=CancelledError()>
asyncio.exceptions.CancelledError
2022-03-06 07:29:51 ERROR: _GatheringFuture exception was never retrieved
future: <_GatheringFuture finished exception=CancelledError()>
asyncio.exceptions.CancelledError
2022-03-06 09:07:35 ERROR: _GatheringFuture exception was never retrieved
future: <_GatheringFuture finished exception=CancelledError()>
asyncio.exceptions.CancelledError
2022-03-06 09:42:50 ERROR: _GatheringFuture exception was never retrieved
future: <_GatheringFuture finished exception=CancelledError()>
asyncio.exceptions.CancelledError
2022-03-06 11:39:32 ERROR: _GatheringFuture exception was never retrieved
future: <_GatheringFuture finished exception=CancelledError()>
asyncio.exceptions.CancelledError
2022-03-06 12:03:05 ERROR: _GatheringFuture exception was never retrieved
future: <_GatheringFuture finished exception=CancelledError()>
asyncio.exceptions.CancelledError
2022-03-06 12:25:19 WARNING: <module 'time' (built-in)> Kosciuszko#1945 950006161300684830 caused the error "Command "recuit" is not found" using the command recuit
2022-03-06 12:25:19 WARNING: <module 'time' (built-in)> Kosciuszko#1945 950006161300684830 674259612580446230 caused the error "Command "recuit" is not found" using the command recuit
2022-03-06 14:03:39 ERROR: _GatheringFuture exception was never retrieved
future: <_GatheringFuture finished exception=CancelledError()>
asyncio.exceptions.CancelledError
2022-03-06 14:18:16 WARNING: <module 'time' (built-in)> Kosciuszko#1945 950034588464480316 caused the error "Command "sto" is not found" using the command sto
2022-03-06 14:18:16 WARNING: <module 'time' (built-in)> Kosciuszko#1945 950034588464480316 674259612580446230 caused the error "Command "sto" is not found" using the command sto
2022-03-06 14:18:29 ERROR: _GatheringFuture exception was never retrieved
future: <_GatheringFuture finished exception=CancelledError()>
asyncio.exceptions.CancelledError
2022-03-06 14:18:46 ERROR: _GatheringFuture exception was never retrieved
future: <_GatheringFuture finished exception=CancelledError()>
asyncio.exceptions.CancelledError
2022-03-06 14:52:13 ERROR: _GatheringFuture exception was never retrieved
future: <_GatheringFuture finished exception=CancelledError()>
asyncio.exceptions.CancelledError
2022-03-06 17:53:51 ERROR: _GatheringFuture exception was never retrieved
future: <_GatheringFuture finished exception=CancelledError()>
asyncio.exceptions.CancelledError
2022-03-06 18:05:02 ERROR: _GatheringFuture exception was never retrieved
future: <_GatheringFuture finished exception=CancelledError()>
asyncio.exceptions.CancelledError
2022-03-06 20:48:28 ERROR: _GatheringFuture exception was never retrieved
future: <_GatheringFuture finished exception=CancelledError()>
asyncio.exceptions.CancelledError
2022-03-06 22:10:08 ERROR: _GatheringFuture exception was never retrieved
future: <_GatheringFuture finished exception=CancelledError()>
asyncio.exceptions.CancelledError
2022-03-07 00:34:17 ERROR: _GatheringFuture exception was never retrieved
future: <_GatheringFuture finished exception=CancelledError()>
asyncio.exceptions.CancelledError
2022-03-07 06:41:05 ERROR: _GatheringFuture exception was never retrieved
future: <_GatheringFuture finished exception=CancelledError()>
asyncio.exceptions.CancelledError
2022-03-07 08:57:43 ERROR: _GatheringFuture exception was never retrieved
future: <_GatheringFuture finished exception=CancelledError()>
asyncio.exceptions.CancelledError
2022-03-07 11:23:02 ERROR: _GatheringFuture exception was never retrieved
future: <_GatheringFuture finished exception=CancelledError()>
asyncio.exceptions.CancelledError
2022-03-07 16:12:09 ERROR: _GatheringFuture exception was never retrieved
future: <_GatheringFuture finished exception=CancelledError()>
asyncio.exceptions.CancelledError
2022-03-07 17:43:29 ERROR: _GatheringFuture exception was never retrieved
future: <_GatheringFuture finished exception=CancelledError()>
asyncio.exceptions.CancelledError
2022-03-07 18:33:00 ERROR: _GatheringFuture exception was never retrieved
future: <_GatheringFuture finished exception=CancelledError()>
asyncio.exceptions.CancelledError
2022-03-07 19:12:41 ERROR: _GatheringFuture exception was never retrieved
future: <_GatheringFuture finished exception=CancelledError()>
asyncio.exceptions.CancelledError
2022-03-08 03:22:52 ERROR: _GatheringFuture exception was never retrieved
future: <_GatheringFuture finished exception=CancelledError()>
asyncio.exceptions.CancelledError
2022-03-08 03:54:23 ERROR: _GatheringFuture exception was never retrieved
future: <_GatheringFuture finished exception=CancelledError()>
asyncio.exceptions.CancelledError
2022-03-08 04:23:11 ERROR: _GatheringFuture exception was never retrieved
future: <_GatheringFuture finished exception=CancelledError()>
asyncio.exceptions.CancelledError
2022-03-08 06:36:28 ERROR: _GatheringFuture exception was never retrieved
future: <_GatheringFuture finished exception=CancelledError()>
asyncio.exceptions.CancelledError
2022-03-08 16:13:30 ERROR: _GatheringFuture exception was never retrieved
future: <_GatheringFuture finished exception=CancelledError()>
asyncio.exceptions.CancelledError
2022-03-08 17:00:24 ERROR: _GatheringFuture exception was never retrieved
future: <_GatheringFuture finished exception=CancelledError()>
asyncio.exceptions.CancelledError
2022-03-08 17:31:22 ERROR: _GatheringFuture exception was never retrieved
future: <_GatheringFuture finished exception=CancelledError()>
asyncio.exceptions.CancelledError
2022-03-09 08:00:30 ERROR: _GatheringFuture exception was never retrieved
future: <_GatheringFuture finished exception=CancelledError()>
asyncio.exceptions.CancelledError
2022-03-09 08:08:33 ERROR: _GatheringFuture exception was never retrieved
future: <_GatheringFuture finished exception=CancelledError()>
asyncio.exceptions.CancelledError
2022-03-09 16:17:07 ERROR: _GatheringFuture exception was never retrieved
future: <_GatheringFuture finished exception=CancelledError()>
asyncio.exceptions.CancelledError
2022-03-09 18:12:45 ERROR: _GatheringFuture exception was never retrieved
future: <_GatheringFuture finished exception=CancelledError()>
asyncio.exceptions.CancelledError
2022-03-09 19:01:55 ERROR: _GatheringFuture exception was never retrieved
future: <_GatheringFuture finished exception=CancelledError()>
asyncio.exceptions.CancelledError
2022-03-09 19:45:27 ERROR: _GatheringFuture exception was never retrieved
future: <_GatheringFuture finished exception=CancelledError()>
asyncio.exceptions.CancelledError
2022-03-09 20:29:56 WARNING: <module 'time' (built-in)> Lies Kryos#1734 951215281496264745 caused the error "Command "nap" is not found" using the command nap
2022-03-09 20:29:56 WARNING: <module 'time' (built-in)> Lies Kryos#1734 951215281496264745 728444080908140575 caused the error "Command "nap" is not found" using the command nap
2022-03-09 20:30:08 ERROR: _ClientEventTask exception was never retrieved
future: <ClientEventTask state=finished event=on_message coro=<bound method BotBase.on_message of <discord.ext.commands.bot.Bot object at 0x7f1f803667c0>> exception=SystemExit(100)>
Traceback (most recent call last):
  File "/usr/local/lib/python3.8/dist-packages/discord/ext/commands/bot.py", line 606, in _load_from_module_spec
    spec.loader.exec_module(lib)
  File "<frozen importlib._bootstrap_external>", line 848, in exec_module
  File "<frozen importlib._bootstrap>", line 219, in _call_with_frames_removed
  File "/root/Documents/Shard/cogs/recruitment.py", line 11, in <module>
    import aiohttp
  File "/root/Documents/Shard/main.py", line 193, in <module>
  File "/usr/local/lib/python3.8/dist-packages/discord/client.py", line 713, in run
    loop.run_forever()
  File "/usr/lib/python3.8/asyncio/base_events.py", line 570, in run_forever
    self._run_once()
  File "/usr/lib/python3.8/asyncio/base_events.py", line 1859, in _run_once
    handle._run()
  File "/usr/lib/python3.8/asyncio/events.py", line 81, in _run
    self._context.run(self._callback, *self._args)
  File "/usr/local/lib/python3.8/dist-packages/discord/client.py", line 343, in _run_event
    await coro(*args, **kwargs)
  File "/usr/local/lib/python3.8/dist-packages/discord/ext/commands/bot.py", line 979, in on_message
    await self.process_commands(message)
  File "/usr/local/lib/python3.8/dist-packages/discord/ext/commands/bot.py", line 976, in process_commands
    await self.invoke(ctx)
  File "/usr/local/lib/python3.8/dist-packages/discord/ext/commands/bot.py", line 939, in invoke
    await ctx.command.invoke(ctx)
  File "/usr/local/lib/python3.8/dist-packages/discord/ext/commands/core.py", line 863, in invoke
    await injected(*ctx.args, **ctx.kwargs)
  File "/usr/local/lib/python3.8/dist-packages/discord/ext/commands/core.py", line 85, in wrapped
    ret = await coro(*args, **kwargs)
  File "/root/Documents/Shard/main.py", line 108, in shut_down
  File "/usr/lib/python3.8/_sitebuiltins.py", line 26, in __call__
    raise SystemExit(code)
SystemExit: 100
2022-03-09 20:30:08 ERROR: _GatheringFuture exception was never retrieved
future: <_GatheringFuture finished exception=CancelledError()>
asyncio.exceptions.CancelledError
2022-03-09 20:32:52 ERROR: Task exception was never retrieved
future: <Task finished name='Task-1' coro=<setup.<locals>.monthly_recruiter_scheduler() done, defined at /root/Documents/Shard/cogs/recruitment.py:520> exception=AttributeError("'NoneType' object has no attribute 'send'")>
Traceback (most recent call last):
  File "/root/Documents/Shard/cogs/recruitment.py", line 532, in monthly_recruiter_scheduler
    await crashchannel.send(f"Monthly recruiter next run: {monthlyjob.next_run_time}")
AttributeError: 'NoneType' object has no attribute 'send'

During handling of the above exception, another exception occurred:

Traceback (most recent call last):
  File "/root/Documents/Shard/cogs/recruitment.py", line 534, in monthly_recruiter_scheduler
    await crashchannel.send(error)
AttributeError: 'NoneType' object has no attribute 'send'
2022-03-09 20:33:29 WARNING: 2022-03-09 20:32:52 Lies Kryos#1734 951216178620153886 caused the error "Command "view_templte" is not found" using the command view_templte
2022-03-09 20:33:29 WARNING: 2022-03-09 20:32:52 Lies Kryos#1734 951216178620153886 caused the error "Command "view_templte" is not found" using the command view_templte
2022-03-09 21:00:19 ERROR: Task exception was never retrieved
future: <Task finished name='Task-1' coro=<setup.<locals>.monthly_recruiter_scheduler() done, defined at /root/Documents/Shard/cogs/recruitment.py:520> exception=AttributeError("'NoneType' object has no attribute 'send'")>
Traceback (most recent call last):
  File "/root/Documents/Shard/cogs/recruitment.py", line 532, in monthly_recruiter_scheduler
    await crashchannel.send(f"Monthly recruiter next run: {monthlyjob.next_run_time}")
AttributeError: 'NoneType' object has no attribute 'send'

During handling of the above exception, another exception occurred:

Traceback (most recent call last):
  File "/root/Documents/Shard/cogs/recruitment.py", line 534, in monthly_recruiter_scheduler
    await crashchannel.send(error)
AttributeError: 'NoneType' object has no attribute 'send'
2022-03-09 21:02:24 WARNING: 2022-03-09 21:00:19 Rock boi#1982 951223455292981258 caused the error "pool is closed" using the command recruit
2022-03-09 21:03:32 WARNING: 2022-03-09 21:00:19 Lies Kryos#1734 951223738093944914 caused the error "Command "recurit" is not found" using the command recurit
2022-03-09 21:03:32 WARNING: 2022-03-09 21:00:19 Lies Kryos#1734 951223738093944914 caused the error "Command "recurit" is not found" using the command recurit
2022-03-09 21:03:35 WARNING: 2022-03-09 21:00:19 Lies Kryos#1734 951223751247278130 caused the error "pool is closed" using the command recruit
2022-03-09 21:04:52 ERROR: _GatheringFuture exception was never retrieved
future: <_GatheringFuture finished exception=CancelledError()>
asyncio.exceptions.CancelledError
2022-03-09 21:05:00 ERROR: Task exception was never retrieved
future: <Task finished name='Task-1' coro=<setup.<locals>.monthly_recruiter_scheduler() done, defined at /root/Documents/Shard/cogs/recruitment.py:520> exception=AttributeError("'NoneType' object has no attribute 'send'")>
Traceback (most recent call last):
  File "/root/Documents/Shard/cogs/recruitment.py", line 532, in monthly_recruiter_scheduler
    await crashchannel.send(f"Monthly recruiter next run: {monthlyjob.next_run_time}")
AttributeError: 'NoneType' object has no attribute 'send'

During handling of the above exception, another exception occurred:

Traceback (most recent call last):
  File "/root/Documents/Shard/cogs/recruitment.py", line 534, in monthly_recruiter_scheduler
    await crashchannel.send(error)
AttributeError: 'NoneType' object has no attribute 'send'
2022-03-10 00:15:25 ERROR: _GatheringFuture exception was never retrieved
future: <_GatheringFuture finished exception=CancelledError()>
asyncio.exceptions.CancelledError
2022-03-10 00:25:18 WARNING: 2022-03-09 21:05:00 Frogge#5370 951274517274165329 caused the error "Command "m" is not found" using the command m
2022-03-10 00:25:18 WARNING: 2022-03-09 21:05:00 Frogge#5370 951274517274165329 caused the error "Command "m" is not found" using the command m
2022-03-10 00:25:27 WARNING: 2022-03-09 21:05:00 Frogge#5370 951274554922262539 caused the error "Command "recruitm" is not found" using the command recruitm
2022-03-10 00:25:27 WARNING: 2022-03-09 21:05:00 Frogge#5370 951274554922262539 caused the error "Command "recruitm" is not found" using the command recruitm
2022-03-10 00:25:39 WARNING: 2022-03-09 21:05:00 Frogge#5370 951274603605536838 caused the error "Command "recruit_m" is not found" using the command recruit_m
2022-03-10 00:25:39 WARNING: 2022-03-09 21:05:00 Frogge#5370 951274603605536838 caused the error "Command "recruit_m" is not found" using the command recruit_m
2022-03-10 06:42:20 ERROR: _GatheringFuture exception was never retrieved
future: <_GatheringFuture finished exception=CancelledError()>
asyncio.exceptions.CancelledError
2022-03-10 07:09:23 ERROR: _GatheringFuture exception was never retrieved
future: <_GatheringFuture finished exception=CancelledError()>
asyncio.exceptions.CancelledError
2022-03-10 16:12:13 ERROR: _GatheringFuture exception was never retrieved
future: <_GatheringFuture finished exception=CancelledError()>
asyncio.exceptions.CancelledError
2022-03-10 20:40:33 ERROR: _GatheringFuture exception was never retrieved
future: <_GatheringFuture finished exception=CancelledError()>
asyncio.exceptions.CancelledError
2022-03-10 23:06:50 ERROR: _GatheringFuture exception was never retrieved
future: <_GatheringFuture finished exception=CancelledError()>
asyncio.exceptions.CancelledError
2022-03-11 01:45:48 ERROR: _GatheringFuture exception was never retrieved
future: <_GatheringFuture finished exception=CancelledError()>
asyncio.exceptions.CancelledError
2022-03-11 03:22:11 WARNING: 2022-03-09 21:05:00 Lies Kryos#1734 951681419330068560 caused the error "Extension 'cogs.dispatches' has not been loaded." using the command reload
2022-03-11 03:35:04 WARNING: 2022-03-09 21:05:00 Lies Kryos#1734 951684661296386118 caused the error "Extension 'cogs.dispatch' has not been loaded." using the command reload
2022-03-11 15:20:38 ERROR: _GatheringFuture exception was never retrieved
future: <_GatheringFuture finished exception=CancelledError()>
asyncio.exceptions.CancelledError
2022-03-11 17:38:33 ERROR: _GatheringFuture exception was never retrieved
future: <_GatheringFuture finished exception=CancelledError()>
asyncio.exceptions.CancelledError
2022-03-11 17:58:09 ERROR: _GatheringFuture exception was never retrieved
future: <_GatheringFuture finished exception=CancelledError()>
asyncio.exceptions.CancelledError
2022-03-11 19:49:13 ERROR: _GatheringFuture exception was never retrieved
future: <_GatheringFuture finished exception=CancelledError()>
asyncio.exceptions.CancelledError
2022-03-11 20:21:52 ERROR: _GatheringFuture exception was never retrieved
future: <_GatheringFuture finished exception=CancelledError()>
asyncio.exceptions.CancelledError
2022-03-11 20:24:00 ERROR: _GatheringFuture exception was never retrieved
future: <_GatheringFuture finished exception=CancelledError()>
asyncio.exceptions.CancelledError
2022-03-12 02:10:01 WARNING: Run time of job "setup.<locals>.waupdate (trigger: cron[month='*', day='*', day_of_week='*', hour='2', minute='10'], next run at: 2022-03-13 02:10:00 UTC)" was missed by 0:00:01.026437
2022-03-12 02:10:01 WARNING: Run time of job "setup.<locals>.waupdate (trigger: cron[month='*', day='*', day_of_week='*', hour='2', minute='10'], next run at: 2022-03-13 02:10:00 UTC)" was missed by 0:00:01.026986
2022-03-12 02:10:01 WARNING: Run time of job "setup.<locals>.waupdate (trigger: cron[month='*', day='*', day_of_week='*', hour='2', minute='10'], next run at: 2022-03-13 02:10:00 UTC)" was missed by 0:00:01.027115
2022-03-12 02:10:01 WARNING: Run time of job "setup.<locals>.waupdate (trigger: cron[month='*', day='*', day_of_week='*', hour='2', minute='10'], next run at: 2022-03-13 02:10:00 UTC)" was missed by 0:00:01.027227
2022-03-12 02:10:01 WARNING: Run time of job "setup.<locals>.waupdate (trigger: cron[month='*', day='*', day_of_week='*', hour='2', minute='10'], next run at: 2022-03-13 02:10:00 UTC)" was missed by 0:00:01.027341
2022-03-12 02:10:01 WARNING: Run time of job "setup.<locals>.waupdate (trigger: cron[month='*', day='*', day_of_week='*', hour='2', minute='10'], next run at: 2022-03-13 02:10:00 UTC)" was missed by 0:00:01.027447
2022-03-12 02:10:01 WARNING: Run time of job "setup.<locals>.waupdate (trigger: cron[month='*', day='*', day_of_week='*', hour='2', minute='10'], next run at: 2022-03-13 02:10:00 UTC)" was missed by 0:00:01.027548
2022-03-12 02:10:01 WARNING: Run time of job "setup.<locals>.waupdate (trigger: cron[month='*', day='*', day_of_week='*', hour='2', minute='10'], next run at: 2022-03-13 02:10:00 UTC)" was missed by 0:00:01.027649
2022-03-12 02:10:01 WARNING: Run time of job "setup.<locals>.waupdate (trigger: cron[month='*', day='*', day_of_week='*', hour='2', minute='10'], next run at: 2022-03-13 02:10:00 UTC)" was missed by 0:00:01.027749
2022-03-12 02:10:01 WARNING: Run time of job "setup.<locals>.waupdate (trigger: cron[month='*', day='*', day_of_week='*', hour='2', minute='10'], next run at: 2022-03-13 02:10:00 UTC)" was missed by 0:00:01.027849
2022-03-12 02:15:01 WARNING: Run time of job "setup.<locals>.kaupdate (trigger: cron[month='*', day='*', day_of_week='*', hour='2', minute='15'], next run at: 2022-03-13 02:15:00 UTC)" was missed by 0:00:01.037532
2022-03-12 02:15:01 WARNING: Run time of job "setup.<locals>.kaupdate (trigger: cron[month='*', day='*', day_of_week='*', hour='2', minute='15'], next run at: 2022-03-13 02:15:00 UTC)" was missed by 0:00:01.038098
2022-03-12 02:15:05 ERROR: Job "setup.<locals>.kaupdate (trigger: cron[month='*', day='*', day_of_week='*', hour='2', minute='15'], next run at: 2022-03-13 02:15:00 UTC)" raised an exception
Traceback (most recent call last):
  File "/usr/local/lib/python3.8/dist-packages/apscheduler/executors/base_py3.py", line 30, in run_coroutine_job
    retval = await job.func(*job.args, **job.kwargs)
  File "/root/Documents/Shard/cogs/dispatch.py", line 180, in kaupdate
    "0200 EST.[/i][/size] "
AttributeError: 'NoneType' object has no attribute 'string'
2022-03-12 02:20:01 WARNING: Run time of job "setup.<locals>.gogupdate (trigger: cron[month='*', day='*', day_of_week='*', hour='2', minute='20'], next run at: 2022-03-13 02:20:00 UTC)" was missed by 0:00:01.208441
2022-03-12 10:24:44 ERROR: _GatheringFuture exception was never retrieved
future: <_GatheringFuture finished exception=CancelledError()>
asyncio.exceptions.CancelledError
2022-03-12 11:56:29 ERROR: _GatheringFuture exception was never retrieved
future: <_GatheringFuture finished exception=CancelledError()>
asyncio.exceptions.CancelledError
2022-03-12 13:30:11 ERROR: _GatheringFuture exception was never retrieved
future: <_GatheringFuture finished exception=CancelledError()>
asyncio.exceptions.CancelledError
2022-03-12 13:30:11 ERROR: _GatheringFuture exception was never retrieved
future: <_GatheringFuture finished exception=CancelledError()>
asyncio.exceptions.CancelledError
2022-03-12 13:30:11 ERROR: _GatheringFuture exception was never retrieved
future: <_GatheringFuture finished exception=CancelledError()>
asyncio.exceptions.CancelledError
2022-03-12 13:30:11 ERROR: Fatal error on SSL transport
protocol: <asyncio.sslproto.SSLProtocol object at 0x7f047e6be520>
transport: <_SelectorSocketTransport closing fd=7>
Traceback (most recent call last):
  File "/usr/lib/python3.8/asyncio/selector_events.py", line 910, in write
    n = self._sock.send(data)
OSError: [Errno 9] Bad file descriptor

During handling of the above exception, another exception occurred:

Traceback (most recent call last):
  File "/usr/lib/python3.8/asyncio/sslproto.py", line 685, in _process_write_backlog
    self._transport.write(chunk)
  File "/usr/lib/python3.8/asyncio/selector_events.py", line 916, in write
    self._fatal_error(exc, 'Fatal write error on socket transport')
  File "/usr/lib/python3.8/asyncio/selector_events.py", line 711, in _fatal_error
    self._force_close(exc)
  File "/usr/lib/python3.8/asyncio/selector_events.py", line 723, in _force_close
    self._loop.call_soon(self._call_connection_lost, exc)
  File "/usr/lib/python3.8/asyncio/base_events.py", line 719, in call_soon
    self._check_closed()
  File "/usr/lib/python3.8/asyncio/base_events.py", line 508, in _check_closed
    raise RuntimeError('Event loop is closed')
RuntimeError: Event loop is closed
2022-03-12 08:41:24 ERROR: Task exception was never retrieved
future: <Task finished name='Task-2' coro=<setup.<locals>.monthly_recruiter_scheduler() done, defined at /root/Documents/Shard/cogs/recruitment.py:521> exception=AttributeError("'NoneType' object has no attribute 'send'")>
Traceback (most recent call last):
  File "/root/Documents/Shard/cogs/recruitment.py", line 536, in monthly_recruiter_scheduler
    await crashchannel.send(f"Monthly recruiter next run: {monthlyjob.next_run_time}")
AttributeError: 'NoneType' object has no attribute 'send'

During handling of the above exception, another exception occurred:

Traceback (most recent call last):
  File "/root/Documents/Shard/cogs/recruitment.py", line 538, in monthly_recruiter_scheduler
    await crashchannel.send(error)
AttributeError: 'NoneType' object has no attribute 'send'
2022-03-12 10:14:03 WARNING: 2022-03-12 08:41:24 Misty#3094 952222951325978679 caused the error "Command "recrui" is not found" using the command recrui
2022-03-12 10:14:03 WARNING: 2022-03-12 08:41:24 Misty#3094 952222951325978679 caused the error "Command "recrui" is not found" using the command recrui
2022-03-12 10:15:15 ERROR: _GatheringFuture exception was never retrieved
future: <_GatheringFuture finished exception=CancelledError()>
asyncio.exceptions.CancelledError
2022-03-12 10:17:08 ERROR: _GatheringFuture exception was never retrieved
future: <_GatheringFuture finished exception=CancelledError()>
asyncio.exceptions.CancelledError
2022-03-12 10:46:13 ERROR: _GatheringFuture exception was never retrieved
future: <_GatheringFuture finished exception=CancelledError()>
asyncio.exceptions.CancelledError
2022-03-12 12:13:52 WARNING: 2022-03-12 08:41:24 DM#6277 952253105628672090 caused the error "Command "1?" is not found" using the command 1?
2022-03-12 12:13:52 WARNING: 2022-03-12 08:41:24 DM#6277 952253105628672090 caused the error "Command "1?" is not found" using the command 1?
2022-03-12 12:43:43 ERROR: _GatheringFuture exception was never retrieved
future: <_GatheringFuture finished exception=CancelledError()>
asyncio.exceptions.CancelledError
2022-03-12 14:33:03 ERROR: _GatheringFuture exception was never retrieved
future: <_GatheringFuture finished exception=CancelledError()>
asyncio.exceptions.CancelledError
2022-03-12 16:10:32 ERROR: _GatheringFuture exception was never retrieved
future: <_GatheringFuture finished exception=CancelledError()>
asyncio.exceptions.CancelledError
2022-03-12 16:13:43 ERROR: _GatheringFuture exception was never retrieved
future: <_GatheringFuture finished exception=CancelledError()>
asyncio.exceptions.CancelledError
2022-03-12 16:14:28 WARNING: 2022-03-12 08:41:24 Misty#3094 952313654651527180 caused the error "Command "rtrank" is not found" using the command rtrank
2022-03-12 16:14:28 WARNING: 2022-03-12 08:41:24 Misty#3094 952313654651527180 caused the error "Command "rtrank" is not found" using the command rtrank
2022-03-12 16:14:33 ERROR: _GatheringFuture exception was never retrieved
future: <_GatheringFuture finished exception=CancelledError()>
asyncio.exceptions.CancelledError
2022-03-12 16:21:41 WARNING: 2022-03-12 08:41:24 DolphinDiverBCT#7954 952315470076330095 caused the error "Command "vie_template" is not found" using the command vie_template
2022-03-12 16:21:41 WARNING: 2022-03-12 08:41:24 DolphinDiverBCT#7954 952315470076330095 caused the error "Command "vie_template" is not found" using the command vie_template
2022-03-12 17:00:58 WARNING: 2022-03-12 08:41:24 Rock boi#1982 952325355761463386 caused the error "Command "sto" is not found" using the command sto
2022-03-12 17:00:58 WARNING: 2022-03-12 08:41:24 Rock boi#1982 952325355761463386 caused the error "Command "sto" is not found" using the command sto
2022-03-12 17:01:23 ERROR: _GatheringFuture exception was never retrieved
future: <_GatheringFuture finished exception=CancelledError()>
asyncio.exceptions.CancelledError
2022-03-12 17:02:37 ERROR: _GatheringFuture exception was never retrieved
future: <_GatheringFuture finished exception=CancelledError()>
asyncio.exceptions.CancelledError
2022-03-12 17:24:23 ERROR: _GatheringFuture exception was never retrieved
future: <_GatheringFuture finished exception=CancelledError()>
asyncio.exceptions.CancelledError
2022-03-12 20:19:56 ERROR: _GatheringFuture exception was never retrieved
future: <_GatheringFuture finished exception=CancelledError()>
asyncio.exceptions.CancelledError
2022-03-13 04:10:00 WARNING: Run time of job "setup.<locals>.waupdate (trigger: cron[hour='2', minute='10'], next run at: 2022-03-14 02:10:00 EDT)" was missed by 1:00:00.004667
2022-03-13 04:10:00 WARNING: Run time of job "setup.<locals>.kaupdate (trigger: cron[hour='2', minute='15'], next run at: 2022-03-14 02:15:00 EDT)" was missed by 0:55:00.004983
2022-03-13 04:10:00 WARNING: Run time of job "setup.<locals>.gogupdate (trigger: cron[hour='2', minute='20'], next run at: 2022-03-14 02:20:00 EDT)" was missed by 0:50:00.005099
2022-03-13 07:33:40 ERROR: _GatheringFuture exception was never retrieved
future: <_GatheringFuture finished exception=CancelledError()>
asyncio.exceptions.CancelledError
2022-03-13 09:17:56 ERROR: _GatheringFuture exception was never retrieved
future: <_GatheringFuture finished exception=CancelledError()>
asyncio.exceptions.CancelledError
2022-03-13 11:06:48 ERROR: _GatheringFuture exception was never retrieved
future: <_GatheringFuture finished exception=CancelledError()>
asyncio.exceptions.CancelledError
2022-03-13 11:19:05 ERROR: _GatheringFuture exception was never retrieved
future: <_GatheringFuture finished exception=CancelledError()>
asyncio.exceptions.CancelledError
2022-03-13 11:25:58 ERROR: _GatheringFuture exception was never retrieved
future: <_GatheringFuture finished exception=CancelledError()>
asyncio.exceptions.CancelledError
2022-05-11 07:20:33,442 WARNING: 
2022-05-11 10:03:17,388 WARNING: relation "mod_logs" does not exist
2022-05-11 10:10:15,598 WARNING: column "action_date" does not exist
HINT:  Perhaps you meant to reference the column "blacklist.actiondate".
2022-05-11 10:11:46,672 WARNING: 'NoneType' object has no attribute 'day'
2022-05-11 10:22:52,225 WARNING: 'NoneType' object has no attribute 'day'
2022-05-11 10:23:04,888 WARNING: 'NoneType' object has no attribute 'day'
2022-05-12 11:02:43,365 WARNING: 'Message' object has no attribute 'reaction_add'
2022-05-12 12:14:32,329 WARNING: 'NoneType' object has no attribute 'lower'
2022-05-12 12:34:23,694 WARNING: That is not a valid focus. Please use only m, e, or d.
2022-05-12 12:59:58,875 WARNING: That is not a valid focus. Please use only m, e, or d.
2022-05-12 13:01:17,281 WARNING: That is not a valid focus. Please use only m, e, or d.
2022-05-12 13:01:30,922 WARNING: That is not a valid focus. Please use only m, e, or d.
2022-05-12 13:04:01,168 WARNING: invalid input for query argument $4: 637939981691912202 (expected str, got int)
2022-05-12 13:18:35,798 WARNING: password authentication failed for user "postgres"
2022-05-12 13:20:10,682 WARNING: password authentication failed for user "postgres"
2022-05-12 14:35:18,059 WARNING: password authentication failed for user "postgres"
2022-05-12 14:38:04,419 WARNING: password authentication failed for user "postgres"
2022-05-12 14:41:10,533 WARNING: password authentication failed for user "postgres"
2022-05-12 14:45:12,367 WARNING: password authentication failed for user "postgres"
2022-05-12 14:49:42,171 WARNING: password authentication failed for user "postgres"
2022-05-12 15:36:28,425 WARNING: 
2022-05-12 15:37:43,027 WARNING: 
2022-05-12 15:38:31,039 WARNING: 
2022-05-12 15:40:14,441 WARNING: list index out of range
2022-05-12 15:41:21,939 WARNING: 
2022-05-12 15:42:10,896 WARNING: 
2022-05-12 16:02:36,252 WARNING: password authentication failed for user "postgres"
2022-05-12 16:03:28,669 WARNING: password authentication failed for user "postgres"
2022-05-12 16:04:09,040 WARNING: relation "terrains" does not exist
2022-05-12 17:02:15,939 WARNING: relation "terrains" does not exist
2022-05-12 17:04:15,728 WARNING: This event loop is already running
2022-05-12 17:05:57,370 WARNING: 'NoneType' object is not subscriptable
2022-05-12 17:06:20,621 WARNING: This event loop is already running
2022-05-12 17:06:49,785 WARNING: 'NoneType' object is not subscriptable
2022-05-12 17:06:56,117 WARNING: 'NoneType' object is not subscriptable
2022-05-12 17:07:39,710 WARNING: 'NoneType' object is not subscriptable
2022-05-12 17:16:27,213 WARNING: This event loop is already running
2022-05-12 17:18:51,573 WARNING: This event loop is already running
2022-05-12 17:18:51,573 WARNING: This event loop is already running
2022-05-12 17:20:11,210 WARNING: This event loop is already running
2022-05-12 17:20:11,210 WARNING: This event loop is already running
2022-05-12 17:30:53,676 WARNING: a coroutine was expected, got <asyncpg.pool.Pool object at 0xffff98251380>
2022-05-12 18:14:15,437 WARNING: 
2022-05-12 20:09:00,646 WARNING: pool is not initialized
2022-05-12 20:25:24,367 WARNING: 'module' object is not callable
2022-05-12 20:27:21,047 WARNING: 'module' object is not callable
2022-05-12 20:28:50,299 WARNING: 'module' object is not callable
2022-05-12 20:31:49,777 WARNING: local variable 'defenderinfo' referenced before assignment
2022-05-12 20:58:35,613 WARNING: That is not a valid focus. Please use only m, e, or s.
2022-05-12 21:13:51,491 WARNING: local variable 'defenderinfo' referenced before assignment
2022-05-12 21:27:16,253 WARNING: 'NoneType' object is not subscriptable
2022-05-13 01:48:35,673 WARNING: 
2022-05-13 04:56:37,718 WARNING: [Errno 5] Input/output error
2022-05-13 04:57:20,594 WARNING: [Errno 5] Input/output error
2022-05-13 05:01:49,078 WARNING: invalid literal for int() with base 16: 'blue'
2022-05-13 05:04:06,556 WARNING: invalid literal for int() with base 16: 'blue'
2022-05-13 05:05:30,097 WARNING: 'Message' object has no attribute 'reaction_add'
2022-05-13 05:06:21,163 WARNING: invalid literal for int() with base 16: 'blue'
2022-05-13 05:27:52,567 WARNING: invalid literal for int() with base 16: 'blue'
2022-05-13 05:28:11,092 WARNING: invalid literal for int() with base 16: 'blue'
2022-05-13 07:19:35,522 WARNING: column "mod" of relation "mod_logs" does not exist
2022-05-13 07:32:31,119 WARNING: [Errno 5] Input/output error
2022-05-13 07:35:04,582 WARNING: [Errno 5] Input/output error
2022-05-13 08:31:52,225 WARNING: [Errno 5] Input/output error
2022-05-13 09:12:19,236 WARNING: 403 Forbidden (error code: 50003): Cannot execute action on a DM channel
2022-05-13 11:17:06,143 WARNING: [Errno 5] Input/output error
2022-05-13 11:43:53,940 WARNING: [Errno 2] No such file or directory: '/root/Documents/Shard/CNC/Map Files/Province Layers/253.png'
2022-05-13 15:31:32,903 WARNING: 
2022-05-13 15:46:17,019 WARNING: 
2022-05-13 15:49:24,275 WARNING: 
2022-05-13 15:50:46,695 WARNING: 'Message' object has no attribute 'reaction_add'
2022-05-13 18:03:28,355 WARNING: image file is truncated
2022-05-13 21:27:25,252 WARNING: invalid input syntax for type bigint: ""
2022-05-14 00:56:15,229 WARNING: [Errno 2] No such file or directory: '/root/Documents/Shard/CNC/Map Files/Province Layers/204.png'
2022-05-14 02:35:41,534 WARNING: [Errno 2] No such file or directory: '/root/Documents/Shard/CNC/Map Files/Province Layers/246.png'
2022-05-14 05:54:25,956 WARNING: [Errno 2] No such file or directory: '/root/Documents/Shard/CNC/Map Files/Province Layers/246.png'
2022-05-14 09:16:09,003 WARNING: 
2022-05-14 09:17:03,323 WARNING: 
2022-05-14 09:17:52,182 WARNING: 
2022-05-14 09:17:57,488 WARNING: 
2022-05-14 09:18:08,881 WARNING: 
2022-05-14 09:19:01,526 WARNING: 
2022-05-14 10:07:48,039 WARNING: That is not a valid focus. Please use only m, e, or s.
2022-05-14 15:46:29,678 WARNING: 'NoneType' object is not subscriptable
2022-05-14 17:13:49,840 WARNING: 'NoneType' object is not subscriptable
2022-05-14 17:31:05,264 WARNING: 
2022-05-14 17:33:33,843 WARNING: 
2022-05-14 17:33:46,652 WARNING: 
2022-05-14 18:01:29,829 WARNING: 'Message' object has no attribute 'reaction_add'
2022-05-15 00:00:44,979 WARNING: invalid literal for int() with base 16: 'blue'
2022-05-15 00:01:06,499 WARNING: invalid literal for int() with base 16: 'blue'
2022-05-15 02:58:38,989 WARNING: invalid literal for int() with base 16: 'blue'
2022-05-15 03:05:30,104 WARNING: invalid literal for int() with base 16: 'blue'
2022-05-15 03:07:50,166 WARNING: invalid literal for int() with base 16: 'blue'
2022-05-15 04:20:48,196 WARNING: 
2022-05-15 06:00:01,132 WARNING: invalid literal for int() with base 10: '151601.0'
2022-05-15 06:48:24,895 WARNING: [Errno 2] No such file or directory: '/root/Documents/Shard/CNC/Map Files/Province Layers/321.png'
2022-05-15 08:15:30,665 WARNING: image file is truncated
2022-05-15 08:16:13,422 WARNING: cannot identify image file '/root/Documents/Shard/CNC/Map Files/Maps/wargame_provinces.png'
2022-05-15 10:55:36,927 WARNING: 403 Forbidden (error code: 50003): Cannot execute action on a DM channel
2022-05-15 11:14:42,243 WARNING: invalid literal for int() with base 16: 'blue'
2022-05-15 11:14:55,210 WARNING: invalid literal for int() with base 16: 'blue'
2022-05-15 11:15:16,420 WARNING: invalid literal for int() with base 16: 'blue'
2022-05-15 11:34:16,601 WARNING: 403 Forbidden (error code: 50003): Cannot execute action on a DM channel
2022-05-15 11:34:35,750 WARNING: 504 Gateway Time-out (error code: 0): <!DOCTYPE html>
<!--[if lt IE 7]> <html class="no-js ie6 oldie" lang="en-US"> <![endif]-->
<!--[if IE 7]>    <html class="no-js ie7 oldie" lang="en-US"> <![endif]-->
<!--[if IE 8]>    <html class="no-js ie8 oldie" lang="en-US"> <![endif]-->
<!--[if gt IE 8]><!--> <html class="no-js" lang="en-US"> <!--<![endif]-->
<head>


<title>discord.com | 504: Gateway time-out</title>
<meta charset="UTF-8" />
<meta http-equiv="Content-Type" content="text/html; charset=UTF-8" />
<meta http-equiv="X-UA-Compatible" content="IE=Edge" />
<meta name="robots" content="noindex, nofollow" />
<meta name="viewport" content="width=device-width,initial-scale=1" />
<link rel="stylesheet" id="cf_styles-css" href="/cdn-cgi/styles/main.css" />


<script>
(function(){if(document.addEventListener&&window.XMLHttpRequest&&JSON&&JSON.stringify){var e=function(a){var c=document.getElementById("error-feedback-survey"),d=document.getElementById("error-feedback-success"),b=new XMLHttpRequest;a={event:"feedback clicked",properties:{errorCode:504,helpful:a,version:1}};b.open("POST","https://sparrow.cloudflare.com/api/v1/event");b.setRequestHeader("Content-Type","application/json");b.setRequestHeader("Sparrow-Source-Key","c771f0e4b54944bebf4261d44bd79a1e");
b.send(JSON.stringify(a));c.classList.add("feedback-hidden");d.classList.remove("feedback-hidden")};document.addEventListener("DOMContentLoaded",function(){var a=document.getElementById("error-feedback"),c=document.getElementById("feedback-button-yes"),d=document.getElementById("feedback-button-no");"classList"in a&&(a.classList.remove("feedback-hidden"),c.addEventListener("click",function(){e(!0)}),d.addEventListener("click",function(){e(!1)}))})}})();
</script>

</head>
<body>
<div id="cf-wrapper">

    

    <div id="cf-error-details" class="p-0">
        <header class="mx-auto pt-10 lg:pt-6 lg:px-8 w-240 lg:w-full mb-8">
            <h1 class="inline-block sm:block sm:mb-2 font-light text-60 lg:text-4xl text-black-dark leading-tight mr-2">
              
              <span class="cf-error-type">Error</span>
              <span class="cf-error-code">504</span>
            </h1>
            <span class="inline-block sm:block font-mono text-15 lg:text-sm lg:leading-relaxed">Ray ID: 70bcf00a4a5a9c8b &bull;</span>
            <span class="inline-block sm:block font-mono text-15 lg:text-sm lg:leading-relaxed">2022-05-15 15:34:35 UTC</span>
            <h2 class="text-gray-600 leading-1.3 text-3xl font-light">Gateway time-out</h2>
        </header>
        
        <div class="my-8 bg-gradient-gray">
            <div class="w-240 lg:w-full mx-auto">
                <div class="clearfix md:px-8">
                  
<div id="cf-browser-status" class=" relative w-1/3 md:w-full py-15 md:p-0 md:py-8 md:text-left md:border-solid md:border-0 md:border-b md:border-gray-400 overflow-hidden float-left md:float-none text-center">
  <div class="relative mb-10 md:m-0">
    <span class="cf-icon-browser block md:hidden h-20 bg-center bg-no-repeat"></span>
    <span class="cf-icon-ok w-12 h-12 absolute left-1/2 md:left-auto md:right-0 md:top-0 -ml-6 -bottom-4"></span>
  </div>
  <span class="md:block w-full truncate">You</span>
  <h3 class="md:inline-block mt-3 md:mt-0 text-2xl text-gray-600 font-light leading-1.3">Browser</h3>
  <span class="leading-1.3 text-2xl text-green-success">Working</span>
</div>

<div id="cf-cloudflare-status" class=" relative w-1/3 md:w-full py-15 md:p-0 md:py-8 md:text-left md:border-solid md:border-0 md:border-b md:border-gray-400 overflow-hidden float-left md:float-none text-center">
  <div class="relative mb-10 md:m-0">
    <span class="cf-icon-cloud block md:hidden h-20 bg-center bg-no-repeat"></span>
    <span class="cf-icon-ok w-12 h-12 absolute left-1/2 md:left-auto md:right-0 md:top-0 -ml-6 -bottom-4"></span>
  </div>
  <span class="md:block w-full truncate">Ashburn</span>
  <h3 class="md:inline-block mt-3 md:mt-0 text-2xl text-gray-600 font-light leading-1.3">Cloudflare</h3>
  <span class="leading-1.3 text-2xl text-green-success">Working</span>
</div>

<div id="cf-host-status" class="cf-error-source relative w-1/3 md:w-full py-15 md:p-0 md:py-8 md:text-left md:border-solid md:border-0 md:border-b md:border-gray-400 overflow-hidden float-left md:float-none text-center">
  <div class="relative mb-10 md:m-0">
    <span class="cf-icon-server block md:hidden h-20 bg-center bg-no-repeat"></span>
    <span class="cf-icon-error w-12 h-12 absolute left-1/2 md:left-auto md:right-0 md:top-0 -ml-6 -bottom-4"></span>
  </div>
  <span class="md:block w-full truncate">discord.com</span>
  <h3 class="md:inline-block mt-3 md:mt-0 text-2xl text-gray-600 font-light leading-1.3">Host</h3>
  <span class="leading-1.3 text-2xl text-red-error">Error</span>
</div>

                </div>
              
            </div>
        </div>

        <div class="w-240 lg:w-full mx-auto mb-8 lg:px-8">
            <div class="clearfix">
                <div class="w-1/2 md:w-full float-left pr-6 md:pb-10 md:pr-0 leading-relaxed">
                    <h2 class="text-3xl font-normal leading-1.3 mb-4">What happened?</h2>
                    <p>The web server reported a gateway time-out error.</p>
                </div>
              
                <div class="w-1/2 md:w-full float-left leading-relaxed">
                    <h2 class="text-3xl font-normal leading-1.3 mb-4">What can I do?</h2>
                    <p class="mb-6">Please try again in a few minutes.</p>
                </div>
            </div>
              
        </div>

        <div class="feedback-hidden py-8 text-center" id="error-feedback">
    <div id="error-feedback-survey" class="footer-line-wrapper">
        Was this page helpful?
        <button class="border border-solid bg-white cf-button cursor-pointer ml-4 px-4 py-2 rounded" id="feedback-button-yes" type="button">Yes</button>
        <button class="border border-solid bg-white cf-button cursor-pointer ml-4 px-4 py-2 rounded" id="feedback-button-no" type="button">No</button>
    </div>
    <div class="feedback-success feedback-hidden" id="error-feedback-success">
        Thank you for your feedback!
    </div>
</div>


        <div class="cf-error-footer cf-wrapper w-240 lg:w-full py-10 sm:py-4 sm:px-8 mx-auto text-center sm:text-left border-solid border-0 border-t border-gray-300">
  <p class="text-13">
    <span class="cf-footer-item sm:block sm:mb-1">Cloudflare Ray ID: <strong class="font-semibold">70bcf00a4a5a9c8b</strong></span>
    <span class="cf-footer-separator sm:hidden">&bull;</span>
    <span class="cf-footer-item sm:block sm:mb-1"><span>Your IP</span>: 129.80.78.252</span>
    <span class="cf-footer-separator sm:hidden">&bull;</span>
    <span class="cf-footer-item sm:block sm:mb-1"><span>Performance &amp; security by</span> <a rel="noopener noreferrer" href="https://www.cloudflare.com/5xx-error-landing" id="brand_link" target="_blank">Cloudflare</a></span>
    
  </p>
</div><!-- /.error-footer -->


    </div>
</div>
</body>
</html>


2022-05-15 11:34:35,851 WARNING: 400 Bad Request (error code: 50035): Invalid Form Body
In content: Must be 4000 or fewer in length.
2022-05-15 11:37:56,749 WARNING: 403 Forbidden (error code: 50003): Cannot execute action on a DM channel
2022-05-15 11:38:08,749 WARNING: 403 Forbidden (error code: 50003): Cannot execute action on a DM channel
2022-05-15 11:40:20,116 WARNING: 403 Forbidden (error code: 50003): Cannot execute action on a DM channel
2022-05-15 12:00:00,527 WARNING: invalid literal for int() with base 10: '151601.0'
2022-05-15 12:08:31,566 WARNING: image file is truncated
2022-05-15 12:41:25,212 WARNING: 
2022-05-15 12:42:04,902 WARNING: 
2022-05-15 12:47:02,573 WARNING: image file is truncated
2022-05-15 12:55:36,145 WARNING: 
2022-05-15 13:30:44,379 WARNING: 'NoneType' object is not subscriptable
2022-05-15 13:45:50,090 WARNING: invalid input syntax for type bigint: ""
2022-05-15 14:25:21,640 WARNING: image file is truncated
2022-05-15 14:25:37,607 WARNING: image file is truncated
2022-05-15 14:26:13,844 WARNING: image file is truncated
2022-05-15 14:27:24,572 WARNING: image file is truncated
