2022-02-27 18:48:59 WARNING: <module 'time' (built-in)> Lies Kryos#1734 947566000801468517 728444080908140575 caused the error "password authentication failed for user "LyesKryos"" using the command recruit
2022-02-28 15:00:15 WARNING: <module 'time' (built-in)> Lies Kryos#1734 947870823719534622 728444080908140575 caused the error "password authentication failed for user "postgres"" using the command recruit
2022-02-28 15:02:15 WARNING: <module 'time' (built-in)> Lies Kryos#1734 947871330173333564 728444080908140575 caused the error "relation "recruitment" does not exist" using the command recruit
2022-02-28 15:25:28 WARNING: <module 'time' (built-in)> Obv_Atlas#6021 947877170179633152 caused the error "Command "template" is not found" using the command template
2022-02-28 15:25:28 WARNING: <module 'time' (built-in)> Obv_Atlas#6021 947877170179633152 674259612580446230 caused the error "Command "template" is not found" using the command template
2022-02-28 15:27:37 WARNING: <module 'time' (built-in)> Obv_Atlas#6021 947877711244836874 caused the error "Command "register_template" is not found" using the command register_template
2022-02-28 15:27:37 WARNING: <module 'time' (built-in)> Obv_Atlas#6021 947877711244836874 674259612580446230 caused the error "Command "register_template" is not found" using the command register_template
2022-02-28 15:47:48 WARNING: <module 'time' (built-in)> Lies Kryos#1734 947882790198861907 728444080908140575 caused the error "Extension 'cogs.recruitment' raised an error: RuntimeError: asyncio.run() cannot be called from a running event loop" using the command reload
2022-02-28 15:52:39 WARNING: <module 'time' (built-in)> Lies Kryos#1734 947884012473577482 728444080908140575 caused the error "Extension 'cogs.recruitment' raised an error: RuntimeError: This event loop is already running" using the command load
2022-02-28 15:58:36 WARNING: <module 'time' (built-in)> Lies Kryos#1734 947885510616051743 728444080908140575 caused the error "Extension 'cogs.recruitment' raised an error: AttributeError: '_UnixSelectorEventLoop' object has no attribute 'run'" using the command load
2022-02-28 16:03:56 WARNING: <module 'time' (built-in)> Lies Kryos#1734 947886852185145365 728444080908140575 caused the error "Extension 'cogs.recruitment' is already loaded." using the command load
2022-02-28 19:02:43 ERROR: _GatheringFuture exception was never retrieved
future: <_GatheringFuture finished exception=OSError(5, 'Input/output error')>
Traceback (most recent call last):
  File "/root/Documents/Shard/cogs/recruitment.py", line 82, in recruitment
    nnsoup = BeautifulSoup(newnationsraw, "lxml")
  File "/usr/local/lib/python3.8/dist-packages/bs4/__init__.py", line 245, in __init__
    raise FeatureNotFound(
bs4.FeatureNotFound: Couldn't find a tree builder with the features you requested: lxml. Do you need to install a parser library?

During handling of the above exception, another exception occurred:

Traceback (most recent call last):
  File "/root/Documents/Shard/cogs/recruitment.py", line 126, in recruitment
    await ctx.send(error)
OSError: [Errno 5] Input/output error
2022-02-28 19:04:00 ERROR: _GatheringFuture exception was never retrieved
future: <_GatheringFuture finished exception=OSError(5, 'Input/output error')>
Traceback (most recent call last):
  File "/root/Documents/Shard/cogs/recruitment.py", line 82, in recruitment
    nnsoup = BeautifulSoup(newnationsraw, "lxml")
  File "/usr/local/lib/python3.8/dist-packages/bs4/__init__.py", line 245, in __init__
    raise FeatureNotFound(
bs4.FeatureNotFound: Couldn't find a tree builder with the features you requested: lxml. Do you need to install a parser library?

During handling of the above exception, another exception occurred:

Traceback (most recent call last):
  File "/root/Documents/Shard/cogs/recruitment.py", line 126, in recruitment
    await ctx.send(error)
OSError: [Errno 5] Input/output error
2022-02-28 19:05:11 ERROR: _GatheringFuture exception was never retrieved
future: <_GatheringFuture finished exception=NameError("name 'logging' is not defined")>
Traceback (most recent call last):
  File "/root/Documents/Shard/cogs/recruitment.py", line 82, in recruitment
    nnsoup = BeautifulSoup(newnationsraw, "lxml")
  File "/usr/local/lib/python3.8/dist-packages/bs4/__init__.py", line 245, in __init__
    raise FeatureNotFound(
bs4.FeatureNotFound: Couldn't find a tree builder with the features you requested: lxml. Do you need to install a parser library?

During handling of the above exception, another exception occurred:

Traceback (most recent call last):
  File "/root/Documents/Shard/cogs/recruitment.py", line 126, in recruitment
    await ctx.send(error)
NameError: name 'logging' is not defined
2022-02-28 19:05:11 ERROR: _GatheringFuture exception was never retrieved
future: <_GatheringFuture finished exception=CancelledError()>
asyncio.exceptions.CancelledError
2022-02-28 19:05:11 ERROR: _GatheringFuture exception was never retrieved
future: <_GatheringFuture finished exception=CancelledError()>
asyncio.exceptions.CancelledError
2022-02-28 19:05:11 ERROR: _GatheringFuture exception was never retrieved
future: <_GatheringFuture finished exception=OSError(5, 'Input/output error')>
Traceback (most recent call last):
  File "/root/Documents/Shard/cogs/recruitment.py", line 82, in recruitment
    nnsoup = BeautifulSoup(newnationsraw, "lxml")
  File "/usr/local/lib/python3.8/dist-packages/bs4/__init__.py", line 245, in __init__
    raise FeatureNotFound(
bs4.FeatureNotFound: Couldn't find a tree builder with the features you requested: lxml. Do you need to install a parser library?

During handling of the above exception, another exception occurred:

Traceback (most recent call last):
  File "/root/Documents/Shard/cogs/recruitment.py", line 126, in recruitment
    await ctx.send(error)
OSError: [Errno 5] Input/output error
2022-02-28 19:07:34 ERROR: Task exception was never retrieved
future: <Task finished name='Task-1' coro=<setup.<locals>.monthly_recruiter_scheduler() done, defined at /root/Documents/Shard/cogs/recruitment.py:520> exception=AttributeError("'NoneType' object has no attribute 'send'")>
Traceback (most recent call last):
  File "/root/Documents/Shard/cogs/recruitment.py", line 532, in monthly_recruiter_scheduler
    await crashchannel.send(f"Monthly recruiter next run: {monthlyjob.next_run_time}")
AttributeError: 'NoneType' object has no attribute 'send'

During handling of the above exception, another exception occurred:

Traceback (most recent call last):
  File "/root/Documents/Shard/cogs/recruitment.py", line 534, in monthly_recruiter_scheduler
    await crashchannel.send(error)
AttributeError: 'NoneType' object has no attribute 'send'
2022-02-28 19:08:21 ERROR: _GatheringFuture exception was never retrieved
future: <_GatheringFuture finished exception=CancelledError()>
asyncio.exceptions.CancelledError
2022-02-28 19:10:23 ERROR: _GatheringFuture exception was never retrieved
future: <_GatheringFuture finished exception=CancelledError()>
asyncio.exceptions.CancelledError
2022-02-28 19:21:54 ERROR: Task exception was never retrieved
future: <Task finished name='Task-1' coro=<setup.<locals>.monthly_recruiter_scheduler() done, defined at /root/Documents/Shard/cogs/recruitment.py:520> exception=AttributeError("'NoneType' object has no attribute 'send'")>
Traceback (most recent call last):
  File "/root/Documents/Shard/cogs/recruitment.py", line 532, in monthly_recruiter_scheduler
    await crashchannel.send(f"Monthly recruiter next run: {monthlyjob.next_run_time}")
AttributeError: 'NoneType' object has no attribute 'send'

During handling of the above exception, another exception occurred:

Traceback (most recent call last):
  File "/root/Documents/Shard/cogs/recruitment.py", line 534, in monthly_recruiter_scheduler
    await crashchannel.send(error)
AttributeError: 'NoneType' object has no attribute 'send'
2022-02-28 22:47:49 ERROR: Task exception was never retrieved
future: <Task finished name='Task-1' coro=<setup.<locals>.monthly_recruiter_scheduler() done, defined at /root/Documents/Shard/cogs/recruitment.py:520> exception=AttributeError("'NoneType' object has no attribute 'send'")>
Traceback (most recent call last):
  File "/root/Documents/Shard/cogs/recruitment.py", line 532, in monthly_recruiter_scheduler
    await crashchannel.send(f"Monthly recruiter next run: {monthlyjob.next_run_time}")
AttributeError: 'NoneType' object has no attribute 'send'

During handling of the above exception, another exception occurred:

Traceback (most recent call last):
  File "/root/Documents/Shard/cogs/recruitment.py", line 534, in monthly_recruiter_scheduler
    await crashchannel.send(error)
AttributeError: 'NoneType' object has no attribute 'send'
2022-03-01 03:24:51 ERROR: _GatheringFuture exception was never retrieved
future: <_GatheringFuture finished exception=CancelledError()>
asyncio.exceptions.CancelledError
2022-03-01 13:29:19 WARNING: <module 'time' (built-in)> Dr_Halred_Van_Richards#6410 948210329467367456 caused the error "Command "recuit" is not found" using the command recuit
2022-03-01 13:29:19 WARNING: <module 'time' (built-in)> Dr_Halred_Van_Richards#6410 948210329467367456 674259612580446230 caused the error "Command "recuit" is not found" using the command recuit
2022-03-01 13:29:41 ERROR: _GatheringFuture exception was never retrieved
future: <_GatheringFuture finished exception=CancelledError()>
asyncio.exceptions.CancelledError
2022-03-01 16:37:33 ERROR: _GatheringFuture exception was never retrieved
future: <_GatheringFuture finished exception=CancelledError()>
asyncio.exceptions.CancelledError
2022-03-01 16:41:35 ERROR: _GatheringFuture exception was never retrieved
future: <_GatheringFuture finished exception=CancelledError()>
asyncio.exceptions.CancelledError
2022-03-01 16:45:51 WARNING: <module 'time' (built-in)> DolphinDiverBCT#7954 948259789111169044 674259612580446230 caused the error "'NoneType' object has no attribute 'id'" using the command recruiter
2022-03-01 16:47:15 WARNING: <module 'time' (built-in)> Lies Kryos#1734 948260136533786704 caused the error "Command "instructions" is not found" using the command instructions
2022-03-01 16:47:15 WARNING: <module 'time' (built-in)> Lies Kryos#1734 948260136533786704 674259612580446230 caused the error "Command "instructions" is not found" using the command instructions
2022-03-01 16:49:14 ERROR: _GatheringFuture exception was never retrieved
future: <_GatheringFuture finished exception=CancelledError()>
asyncio.exceptions.CancelledError
2022-03-01 17:55:09 ERROR: _GatheringFuture exception was never retrieved
future: <_GatheringFuture finished exception=CancelledError()>
asyncio.exceptions.CancelledError
2022-03-01 18:33:24 ERROR: _GatheringFuture exception was never retrieved
future: <_GatheringFuture finished exception=CancelledError()>
asyncio.exceptions.CancelledError
2022-03-01 19:25:05 WARNING: <module 'time' (built-in)> Lies Kryos#1734 948299858928885781 674259612580446230 caused the error "'NoneType' object has no attribute 'id'" using the command recruiter
2022-03-01 19:27:49 WARNING: <module 'time' (built-in)> Lies Kryos#1734 948300549051265036 728444080908140575 caused the error "Extension 'cogs.recruiter' has not been loaded." using the command reload
2022-03-01 21:06:38 ERROR: _GatheringFuture exception was never retrieved
future: <_GatheringFuture finished exception=CancelledError()>
asyncio.exceptions.CancelledError
2022-03-01 21:10:58 WARNING: <module 'time' (built-in)> Obv_Atlas#6021 948326507531608114 caused the error "Command "STOP" is not found" using the command STOP
2022-03-01 21:10:58 WARNING: <module 'time' (built-in)> Obv_Atlas#6021 948326507531608114 674259612580446230 caused the error "Command "STOP" is not found" using the command STOP
2022-03-01 23:39:05 ERROR: _GatheringFuture exception was never retrieved
future: <_GatheringFuture finished exception=CancelledError()>
asyncio.exceptions.CancelledError
2022-03-01 23:54:37 ERROR: _GatheringFuture exception was never retrieved
future: <_GatheringFuture finished exception=CancelledError()>
asyncio.exceptions.CancelledError
2022-03-02 08:27:30 ERROR: _GatheringFuture exception was never retrieved
future: <_GatheringFuture finished exception=CancelledError()>
asyncio.exceptions.CancelledError
2022-03-02 16:31:06 ERROR: _GatheringFuture exception was never retrieved
future: <_GatheringFuture finished exception=CancelledError()>
asyncio.exceptions.CancelledError
2022-03-02 17:25:36 ERROR: _GatheringFuture exception was never retrieved
future: <_GatheringFuture finished exception=CancelledError()>
asyncio.exceptions.CancelledError
2022-03-02 17:50:44 ERROR: _GatheringFuture exception was never retrieved
future: <_GatheringFuture finished exception=CancelledError()>
asyncio.exceptions.CancelledError
2022-03-02 18:45:53 ERROR: _GatheringFuture exception was never retrieved
future: <_GatheringFuture finished exception=CancelledError()>
asyncio.exceptions.CancelledError
2022-03-02 20:14:46 ERROR: _GatheringFuture exception was never retrieved
future: <_GatheringFuture finished exception=CancelledError()>
asyncio.exceptions.CancelledError
